# Generated by Django 4.2.20 on 2025-06-01 12:41

from django.conf import settings
from django.db import migrations, models
import django.db.models.deletion
import uuid


class Migration(migrations.Migration):

    initial = True

    dependencies = [
        migrations.swappable_dependency(settings.AUTH_USER_MODEL),
    ]

    operations = [
        migrations.CreateModel(
            name='SalesDataFile',
            fields=[
                ('id', models.UUIDField(default=uuid.uuid4, editable=False, primary_key=True, serialize=False)),
                ('file', models.FileField(upload_to='sales_data/')),
                ('file_name', models.CharField(max_length=255)),
                ('file_type', models.CharField(max_length=50)),
                ('uploaded_at', models.DateTimeField(auto_now_add=True)),
                ('user', models.ForeignKey(on_delete=django.db.models.deletion.CASCADE, related_name='sales_data_files', to=settings.AUTH_USER_MODEL)),
            ],
        ),
        migrations.CreateModel(
            name='SalesAnalysisResult',
            fields=[
                ('id', models.UUIDField(default=uuid.uuid4, editable=False, primary_key=True, serialize=False)),
                ('analysis_data', models.JSONField(blank=True, null=True)),
                ('column_mappings', models.JSONField(blank=True, null=True)),
                ('created_at', models.DateTimeField(auto_now_add=True)),
                ('updated_at', models.DateTimeField(auto_now=True)),
                ('status', models.CharField(default='pending', max_length=50)),
                ('error_message', models.TextField(blank=True, null=True)),
                ('sales_data_file', models.OneToOneField(on_delete=django.db.models.deletion.CASCADE, related_name='analysis_result', to='business_analytics.salesdatafile')),
            ],
        ),
    ]
